<?xml version="1.0"?>
<!-- Using masses and inertia matrices from this paper https://ieeexplore.ieee.org/document/9112185 -->
<robot xmlns:xacro="http://www.ros.org/wiki/xacro">
    <!-- robot as extracted via https://github.com/syuntoku14/fusion2urdf -->
    <xacro:macro name="iiwa14"
        params="robot_name:=^|lbr mode:=^|mock system_config_path:=^|'$(find lbr_description)/ros2_control/lbr_system_config.yaml'">

        <!-- includes -->
        <xacro:include filename="$(find lbr_description)/gazebo/lbr_gazebo.xacro" />
        <xacro:include filename="$(find lbr_description)/ros2_control/lbr_system_interface.xacro" />

        <!-- joint limits via yaml -->
        <xacro:property name="joint_limits_path"
            value="$(find lbr_description)/urdf/iiwa14/joint_limits.yaml" />
        <xacro:property name="joint_limits" value="${xacro.load_yaml(joint_limits_path)}" />

        <!-- constants -->
        <xacro:property name="PI" value="3.1415926535897931" />
        <xacro:property name="joint_damping" value="10.0" />
        <xacro:property name="joint_friction" value="0.1" />

        <!-- macros for gazebo / mock / hardware -->
        <xacro:lbr_gazebo robot_name="${robot_name}" />
        <xacro:lbr_system_interface
            robot_name="${robot_name}"
            mode="${mode}"
            joint_limits="${joint_limits}"
            system_config_path="${system_config_path}" />

        <link name="${robot_name}_link_0">
            <inertial>
                <origin rpy="0 0 0" xyz="-0.012822 0.0 0.071507" />
                <mass value="7.050378" />
                <inertia ixx="0.031226" ixy="0.0" ixz="0.000871" iyy="0.039697" iyz="0.0"
                    izz="0.043102" />
            </inertial>
            <visual>
                <origin rpy="0 0 0" xyz="0 0 0" />
                <geometry>
                    <mesh filename="package://lbr_description/meshes/iiwa14/visual/link_0.dae" />
                </geometry>
            </visual>
            <collision>
                <origin rpy="0 0 0" xyz="0 0 0" />
                <geometry>
                    <mesh filename="package://lbr_description/meshes/iiwa14/collision/link_0.stl" />
                </geometry>
            </collision>
        </link>

        <joint name="${robot_name}_A1" type="revolute">
            <origin rpy="0 0 0" xyz="0.0 0.0 0.1475" />
            <parent link="${robot_name}_link_0" />
            <child link="${robot_name}_link_1" />
            <axis xyz="0.0 0.0 1.0" />
            <limit
                effort="${joint_limits['A1']['effort']}"
                lower="${joint_limits['A1']['lower'] * PI / 180}"
                upper="${joint_limits['A1']['upper'] * PI / 180}"
                velocity="${joint_limits['A1']['velocity'] * PI / 180}" />
            <dynamics damping="${joint_damping}" friction="${joint_friction}" />
        </joint>

        <link name="${robot_name}_link_1">
            <inertial>
                <origin rpy="0 0 0" xyz="-0.018 0.0455 -0.1050" />
                <mass value="1.0" />
                <inertia ixx="0.5468" ixy="-0.0082" ixz="0.0116" iyy="0.6997" iyz="-0.0136"
                    izz="0.1625" />
            </inertial>
            <visual>
                <origin rpy="0 0 0" xyz="0.0 0.0 -0.1475" />
                <geometry>
                    <mesh filename="package://lbr_description/meshes/iiwa14/visual/link_1.dae" />
                </geometry>
            </visual>
            <collision>
                <origin rpy="0 0 0" xyz="0.0 0.0 -0.1475" />
                <geometry>
                    <mesh filename="package://lbr_description/meshes/iiwa14/collision/link_1.stl" />
                </geometry>
            </collision>
        </link>

        <joint name="${robot_name}_A2" type="revolute">
            <origin rpy="0 0 0" xyz="0.0 -0.01 0.2125" />
            <parent link="${robot_name}_link_1" />
            <child link="${robot_name}_link_2" />
            <axis xyz="0.0 1.0 0.0" />
            <limit
                effort="${joint_limits['A2']['effort']}"
                lower="${joint_limits['A2']['lower'] * PI / 180}"
                upper="${joint_limits['A2']['upper'] * PI / 180}"
                velocity="${joint_limits['A2']['velocity'] * PI / 180}" />
            <dynamics damping="${joint_damping}" friction="${joint_friction}" />
        </joint>

        <link name="${robot_name}_link_2">
            <inertial>
                <origin rpy="0 0 0" xyz="0.0219 0.1218 0.0500" />
                <mass value="5.5609" />
                <inertia ixx="0.0022" ixy="7.3e-05" ixz="-7.3e-05" iyy="7.3e-04" iyz="-7.3e-05"
                    izz="0.0029" />
            </inertial>
            <visual>
                <origin rpy="0 0 0" xyz="0.0 0.01 -0.36" />
                <geometry>
                    <mesh filename="package://lbr_description/meshes/iiwa14/visual/link_2.dae" />
                </geometry>
            </visual>
            <collision>
                <origin rpy="0 0 0" xyz="0.0 0.01 -0.36" />
                <geometry>
                    <mesh filename="package://lbr_description/meshes/iiwa14/collision/link_2.stl" />
                </geometry>
            </collision>
        </link>

        <joint name="${robot_name}_A3" type="revolute">
            <origin rpy="0 0 0" xyz="0.0 0.01 0.228" />
            <parent link="${robot_name}_link_2" />
            <child link="${robot_name}_link_3" />
            <axis xyz="0.0 0.0 1.0" />
            <limit
                effort="${joint_limits['A3']['effort']}"
                lower="${joint_limits['A3']['lower'] * PI / 180}"
                upper="${joint_limits['A3']['upper'] * PI / 180}"
                velocity="${joint_limits['A3']['velocity'] * PI / 180}" />
            <dynamics damping="${joint_damping}" friction="${joint_friction}" />
        </joint>

        <link name="${robot_name}_link_3">
            <inertial>
                <origin rpy="0 0 0" xyz="-0.0216 0.0500 -0.3000" />
                <mass value="5.9199" />
                <inertia ixx="3.0e-04" ixy="-5.4e-06" ixz="-1.0e-05" iyy="4.0e-04" iyz="-9.8e-06"
                    izz="1.02e-04" />
                <!-- izz is 1.0e.04 in the paper but it seems to cause invalid inertia error -->
            </inertial>
            <visual>
                <origin rpy="0 0 0" xyz="0.0 0.0 -0.588" />
                <geometry>
                    <mesh filename="package://lbr_description/meshes/iiwa14/visual/link_3.dae" />
                </geometry>
            </visual>
            <collision>
                <origin rpy="0 0 0" xyz="0.0 0.0 -0.588" />
                <geometry>
                    <mesh filename="package://lbr_description/meshes/iiwa14/collision/link_3.stl" />
                </geometry>
            </collision>
        </link>

        <joint name="${robot_name}_A4" type="revolute">
            <origin rpy="0 0 0" xyz="0.0 0.0105 0.192" />
            <parent link="${robot_name}_link_3" />
            <child link="${robot_name}_link_4" />
            <axis xyz="0.0 -1.0 0.0" />
            <limit
                effort="${joint_limits['A4']['effort']}"
                lower="${joint_limits['A4']['lower'] * PI / 180}"
                upper="${joint_limits['A4']['upper'] * PI / 180}"
                velocity="${joint_limits['A4']['velocity'] * PI / 180}" />
            <dynamics damping="${joint_damping}" friction="${joint_friction}" />
        </joint>

        <link name="${robot_name}_link_4">
            <inertial>
                <origin rpy="0 0 0" xyz="0.0161 -0.2004 -0.0425" />
                <mass value="6.0000" />
                <inertia ixx="3.0e-04" ixy="-9.9e-06" ixz="9.9e-06" iyy="1.03e-04" iyz="-1.0e-05"
                    izz="4.0e-04" />
                <!-- iyy is 1.0e.05 in the paper but it seems to cause invalid inertia error -->

            </inertial>
            <visual>
                <origin rpy="0 0 0" xyz="0.0 -0.0105 -0.78" />
                <geometry>
                    <mesh filename="package://lbr_description/meshes/iiwa14/visual/link_4.dae" />
                </geometry>
            </visual>
            <collision>
                <origin rpy="0 0 0" xyz="0.0 -0.0105 -0.78" />
                <geometry>
                    <mesh filename="package://lbr_description/meshes/iiwa14/collision/link_4.stl" />
                </geometry>
            </collision>
        </link>

        <joint name="${robot_name}_A5" type="revolute">
            <origin rpy="0 0 0" xyz="0.0 -0.0105 0.2075" />
            <parent link="${robot_name}_link_4" />
            <child link="${robot_name}_link_5" />
            <axis xyz="0.0 0.0 1.0" />
            <limit
                effort="${joint_limits['A5']['effort']}"
                lower="${joint_limits['A5']['lower'] * PI / 180}"
                upper="${joint_limits['A5']['upper'] * PI / 180}"
                velocity="${joint_limits['A5']['velocity'] * PI / 180}" />
            <dynamics damping="${joint_damping}" friction="${joint_friction}" />
        </joint>

        <link name="${robot_name}_link_5">
            <inertial>
                <origin rpy="0 0 0" xyz="0.00056 0.0131 -0.2390" />
                <mass value="2.9896" />
                <inertia ixx="3.0e-04" ixy="1.0e-05" ixz="-9.8e-06" iyy="3.0e-04" iyz="9.8e-06"
                    izz="1.0e-04" />
            </inertial>
            <visual>
                <origin rpy="0 0 0" xyz="0.0 0.0 -0.9875" />
                <geometry>
                    <mesh filename="package://lbr_description/meshes/iiwa14/visual/link_5.dae" />
                </geometry>
            </visual>
            <collision>
                <origin rpy="0 0 0" xyz="0.0 0.0 -0.9875" />
                <geometry>
                    <mesh filename="package://lbr_description/meshes/iiwa14/collision/link_5.stl" />
                </geometry>
            </collision>
        </link>

        <joint name="${robot_name}_A6" type="revolute">
            <origin rpy="0 0 0" xyz="0.0 -0.0707 0.1925" />
            <parent link="${robot_name}_link_5" />
            <child link="${robot_name}_link_6" />
            <axis xyz="0.0 1.0 0.0" />
            <limit
                effort="${joint_limits['A6']['effort']}"
                lower="${joint_limits['A6']['lower'] * PI / 180}"
                upper="${joint_limits['A6']['upper'] * PI / 180}"
                velocity="${joint_limits['A6']['velocity'] * PI / 180}" />
            <dynamics damping="${joint_damping}" friction="${joint_friction}" />
        </joint>

        <link name="${robot_name}_link_6">
            <inertial>
                <origin rpy="0 0 0" xyz="0.0074 0.1500 -0.0232" />
                <mass value="1.0000" />
                <inertia ixx="1.0e-04" ixy="-9.9e-06" ixz="-1.0e-05" iyy="1.0e-04" iyz="9.9e-06"
                    izz="1.0e-04" />
            </inertial>
            <visual>
                <origin rpy="0 0 0" xyz="0.0 0.0707 -1.18" />
                <geometry>
                    <mesh filename="package://lbr_description/meshes/iiwa14/visual/link_6.dae" />
                </geometry>
            </visual>
            <collision>
                <origin rpy="0 0 0" xyz="0.0 0.0707 -1.18" />
                <geometry>
                    <mesh filename="package://lbr_description/meshes/iiwa14/collision/link_6.stl" />
                </geometry>
            </collision>
        </link>

        <joint name="${robot_name}_A7" type="revolute">
            <origin rpy="0 0 0" xyz="0.0 0.0707 0.091" />
            <parent link="${robot_name}_link_6" />
            <child link="${robot_name}_link_7" />
            <axis xyz="0.0 0.0 1.0" />
            <limit
                effort="${joint_limits['A7']['effort']}"
                lower="${joint_limits['A7']['lower'] * PI / 180}"
                upper="${joint_limits['A7']['upper'] * PI / 180}"
                velocity="${joint_limits['A7']['velocity'] * PI / 180}" />
            <dynamics damping="${joint_damping}" friction="${joint_friction}" />
        </joint>

        <link name="${robot_name}_link_7">
            <inertial>
                <origin rpy="0 0 0" xyz="-0.0029 8.1e-04 0.1998" />
                <mass value="3.5296" />
                <inertia ixx="0.0081" ixy="-9.1e-06" ixz="-9.9e-06" iyy="1.0e-04" iyz="-9.9e-06"
                    izz="0.0080" />
                <!-- iyy is 1.0e.05 in the paper but it seems to cause invalid inertia error -->
            </inertial>
            <visual>
                <origin rpy="0 0 0" xyz="0.0 0.0 -1.271" />
                <geometry>
                    <mesh filename="package://lbr_description/meshes/iiwa14/visual/link_7.dae" />
                </geometry>
            </visual>
            <collision>
                <origin rpy="0 0 0" xyz="0.0 0.0 -1.271" />
                <geometry>
                    <mesh filename="package://lbr_description/meshes/iiwa14/collision/link_7.stl" />
                </geometry>
            </collision>
        </link>

        <joint name="${robot_name}_joint_ee" type="fixed">
            <parent link="${robot_name}_link_7" />
            <child link="${robot_name}_link_ee" />
            <origin xyz="0 0 0.035" rpy="0 0 0" />
        </joint>

        <link name="${robot_name}_link_ee">
        </link>
    </xacro:macro>
</robot>